2025-05-22 18:46:41,086 ERROR: Row 736: This Session's transaction has been rolled back due to a previous exception during flush. To begin a new transaction with this Session, first issue Session.rollback(). Original exception was: (raised as a result of Query-invoked autoflush; consider using a session.no_autoflush block if this flush is occurring prematurely)
(psycopg2.errors.UniqueViolation) duplicate key value violates unique constraint "student_aadhar_number_key"
DETAIL:  Key (aadhar_number)=(684639241194) already exists.

[SQL: INSERT INTO student (pen_num, admission_number, aadhar_number, student_name, father_name, mother_name, gender, date_of_birth, date_of_joining, contact_number, village, created_by, updated_at, updated_by) VALUES (%(pen_num)s, %(admission_number)s, %(aadhar_number)s, %(student_name)s, %(father_name)s, %(mother_name)s, %(gender)s, %(date_of_birth)s, %(date_of_joining)s, %(contact_number)s, %(village)s, %(created_by)s, %(updated_at)s, %(updated_by)s) RETURNING student.created_at]
[parameters: {'pen_num': 20976697950, 'admission_number': 1539, 'aadhar_number': 684639241194, 'student_name': 'Sajja Thrunith Chowdry', 'father_name': 'Sajja Vijay Kumar', 'mother_name': 'Sajja Divya', 'gender': 'Male', 'date_of_birth': datetime.date(2012, 10, 17), 'date_of_joining': datetime.date(2022, 5, 24), 'contact_number': '6281446585', 'village': 'Hythabad', 'created_by': 'Uthkarsh', 'updated_at': datetime.datetime(2025, 5, 22, 18, 46, 41, 85197), 'updated_by': 'Uthkarsh'}]
(Background on this error at: https://sqlalche.me/e/20/gkpj) (Background on this error at: https://sqlalche.me/e/20/7s2a) [in /media/uthkarsh/HDD1/school_fee/school_final/school/routes.py:1208]
2025-05-22 18:46:41,087 ERROR: Row 737: This Session's transaction has been rolled back due to a previous exception during flush. To begin a new transaction with this Session, first issue Session.rollback(). Original exception was: (raised as a result of Query-invoked autoflush; consider using a session.no_autoflush block if this flush is occurring prematurely)
(psycopg2.errors.UniqueViolation) duplicate key value violates unique constraint "student_aadhar_number_key"
DETAIL:  Key (aadhar_number)=(684639241194) already exists.

[SQL: INSERT INTO student (pen_num, admission_number, aadhar_number, student_name, father_name, mother_name, gender, date_of_birth, date_of_joining, contact_number, village, created_by, updated_at, updated_by) VALUES (%(pen_num)s, %(admission_number)s, %(aadhar_number)s, %(student_name)s, %(father_name)s, %(mother_name)s, %(gender)s, %(date_of_birth)s, %(date_of_joining)s, %(contact_number)s, %(village)s, %(created_by)s, %(updated_at)s, %(updated_by)s) RETURNING student.created_at]
[parameters: {'pen_num': 20976697950, 'admission_number': 1539, 'aadhar_number': 684639241194, 'student_name': 'Sajja Thrunith Chowdry', 'father_name': 'Sajja Vijay Kumar', 'mother_name': 'Sajja Divya', 'gender': 'Male', 'date_of_birth': datetime.date(2012, 10, 17), 'date_of_joining': datetime.date(2022, 5, 24), 'contact_number': '6281446585', 'village': 'Hythabad', 'created_by': 'Uthkarsh', 'updated_at': datetime.datetime(2025, 5, 22, 18, 46, 41, 85197), 'updated_by': 'Uthkarsh'}]
(Background on this error at: https://sqlalche.me/e/20/gkpj) (Background on this error at: https://sqlalche.me/e/20/7s2a) [in /media/uthkarsh/HDD1/school_fee/school_final/school/routes.py:1208]
2025-05-22 18:46:41,088 ERROR: Row 738: This Session's transaction has been rolled back due to a previous exception during flush. To begin a new transaction with this Session, first issue Session.rollback(). Original exception was: (raised as a result of Query-invoked autoflush; consider using a session.no_autoflush block if this flush is occurring prematurely)
(psycopg2.errors.UniqueViolation) duplicate key value violates unique constraint "student_aadhar_number_key"
DETAIL:  Key (aadhar_number)=(684639241194) already exists.

[SQL: INSERT INTO student (pen_num, admission_number, aadhar_number, student_name, father_name, mother_name, gender, date_of_birth, date_of_joining, contact_number, village, created_by, updated_at, updated_by) VALUES (%(pen_num)s, %(admission_number)s, %(aadhar_number)s, %(student_name)s, %(father_name)s, %(mother_name)s, %(gender)s, %(date_of_birth)s, %(date_of_joining)s, %(contact_number)s, %(village)s, %(created_by)s, %(updated_at)s, %(updated_by)s) RETURNING student.created_at]
[parameters: {'pen_num': 20976697950, 'admission_number': 1539, 'aadhar_number': 684639241194, 'student_name': 'Sajja Thrunith Chowdry', 'father_name': 'Sajja Vijay Kumar', 'mother_name': 'Sajja Divya', 'gender': 'Male', 'date_of_birth': datetime.date(2012, 10, 17), 'date_of_joining': datetime.date(2022, 5, 24), 'contact_number': '6281446585', 'village': 'Hythabad', 'created_by': 'Uthkarsh', 'updated_at': datetime.datetime(2025, 5, 22, 18, 46, 41, 85197), 'updated_by': 'Uthkarsh'}]
(Background on this error at: https://sqlalche.me/e/20/gkpj) (Background on this error at: https://sqlalche.me/e/20/7s2a) [in /media/uthkarsh/HDD1/school_fee/school_final/school/routes.py:1208]
2025-05-22 18:46:41,088 ERROR: Row 739: This Session's transaction has been rolled back due to a previous exception during flush. To begin a new transaction with this Session, first issue Session.rollback(). Original exception was: (raised as a result of Query-invoked autoflush; consider using a session.no_autoflush block if this flush is occurring prematurely)
(psycopg2.errors.UniqueViolation) duplicate key value violates unique constraint "student_aadhar_number_key"
DETAIL:  Key (aadhar_number)=(684639241194) already exists.

[SQL: INSERT INTO student (pen_num, admission_number, aadhar_number, student_name, father_name, mother_name, gender, date_of_birth, date_of_joining, contact_number, village, created_by, updated_at, updated_by) VALUES (%(pen_num)s, %(admission_number)s, %(aadhar_number)s, %(student_name)s, %(father_name)s, %(mother_name)s, %(gender)s, %(date_of_birth)s, %(date_of_joining)s, %(contact_number)s, %(village)s, %(created_by)s, %(updated_at)s, %(updated_by)s) RETURNING student.created_at]
[parameters: {'pen_num': 20976697950, 'admission_number': 1539, 'aadhar_number': 684639241194, 'student_name': 'Sajja Thrunith Chowdry', 'father_name': 'Sajja Vijay Kumar', 'mother_name': 'Sajja Divya', 'gender': 'Male', 'date_of_birth': datetime.date(2012, 10, 17), 'date_of_joining': datetime.date(2022, 5, 24), 'contact_number': '6281446585', 'village': 'Hythabad', 'created_by': 'Uthkarsh', 'updated_at': datetime.datetime(2025, 5, 22, 18, 46, 41, 85197), 'updated_by': 'Uthkarsh'}]
(Background on this error at: https://sqlalche.me/e/20/gkpj) (Background on this error at: https://sqlalche.me/e/20/7s2a) [in /media/uthkarsh/HDD1/school_fee/school_final/school/routes.py:1208]
2025-05-22 18:46:41,089 ERROR: Row 740: This Session's transaction has been rolled back due to a previous exception during flush. To begin a new transaction with this Session, first issue Session.rollback(). Original exception was: (raised as a result of Query-invoked autoflush; consider using a session.no_autoflush block if this flush is occurring prematurely)
(psycopg2.errors.UniqueViolation) duplicate key value violates unique constraint "student_aadhar_number_key"
DETAIL:  Key (aadhar_number)=(684639241194) already exists.

[SQL: INSERT INTO student (pen_num, admission_number, aadhar_number, student_name, father_name, mother_name, gender, date_of_birth, date_of_joining, contact_number, village, created_by, updated_at, updated_by) VALUES (%(pen_num)s, %(admission_number)s, %(aadhar_number)s, %(student_name)s, %(father_name)s, %(mother_name)s, %(gender)s, %(date_of_birth)s, %(date_of_joining)s, %(contact_number)s, %(village)s, %(created_by)s, %(updated_at)s, %(updated_by)s) RETURNING student.created_at]
[parameters: {'pen_num': 20976697950, 'admission_number': 1539, 'aadhar_number': 684639241194, 'student_name': 'Sajja Thrunith Chowdry', 'father_name': 'Sajja Vijay Kumar', 'mother_name': 'Sajja Divya', 'gender': 'Male', 'date_of_birth': datetime.date(2012, 10, 17), 'date_of_joining': datetime.date(2022, 5, 24), 'contact_number': '6281446585', 'village': 'Hythabad', 'created_by': 'Uthkarsh', 'updated_at': datetime.datetime(2025, 5, 22, 18, 46, 41, 85197), 'updated_by': 'Uthkarsh'}]
(Background on this error at: https://sqlalche.me/e/20/gkpj) (Background on this error at: https://sqlalche.me/e/20/7s2a) [in /media/uthkarsh/HDD1/school_fee/school_final/school/routes.py:1208]
2025-05-22 18:46:41,089 ERROR: Row 741: This Session's transaction has been rolled back due to a previous exception during flush. To begin a new transaction with this Session, first issue Session.rollback(). Original exception was: (raised as a result of Query-invoked autoflush; consider using a session.no_autoflush block if this flush is occurring prematurely)
(psycopg2.errors.UniqueViolation) duplicate key value violates unique constraint "student_aadhar_number_key"
DETAIL:  Key (aadhar_number)=(684639241194) already exists.

[SQL: INSERT INTO student (pen_num, admission_number, aadhar_number, student_name, father_name, mother_name, gender, date_of_birth, date_of_joining, contact_number, village, created_by, updated_at, updated_by) VALUES (%(pen_num)s, %(admission_number)s, %(aadhar_number)s, %(student_name)s, %(father_name)s, %(mother_name)s, %(gender)s, %(date_of_birth)s, %(date_of_joining)s, %(contact_number)s, %(village)s, %(created_by)s, %(updated_at)s, %(updated_by)s) RETURNING student.created_at]
[parameters: {'pen_num': 20976697950, 'admission_number': 1539, 'aadhar_number': 684639241194, 'student_name': 'Sajja Thrunith Chowdry', 'father_name': 'Sajja Vijay Kumar', 'mother_name': 'Sajja Divya', 'gender': 'Male', 'date_of_birth': datetime.date(2012, 10, 17), 'date_of_joining': datetime.date(2022, 5, 24), 'contact_number': '6281446585', 'village': 'Hythabad', 'created_by': 'Uthkarsh', 'updated_at': datetime.datetime(2025, 5, 22, 18, 46, 41, 85197), 'updated_by': 'Uthkarsh'}]
(Background on this error at: https://sqlalche.me/e/20/gkpj) (Background on this error at: https://sqlalche.me/e/20/7s2a) [in /media/uthkarsh/HDD1/school_fee/school_final/school/routes.py:1208]
